Workbook

Sheet Tổng quan
A1: BỘ TEST CASE — SOFINHUB
A3: Dự án | B3: SofinHub — Nền tảng Cộng đồng & Khóa học trực tuyến
A4: Nguồn tài liệu | B4: SofinHub-BRD.docx (BRD v1.0, 28/09/2026) + backend/docs/API.md, backend/docs/api/*.md, docs/features/*.md, backend/docs/DATABASE.md, backend/prisma/seed* (đợt 30/09/2026), backend/docs/api/admin.md + docs/features/admin-batch1.md (đợt 01/10/2026)
A5: Ngày tạo bộ test case | B5: 29/09/2026 — cập nhật đợt backend Postgres + frontend 30/09/2026 và đợt Admin console 01/10/2026 (xem sheet 'Nhật ký thay đổi')
A6: Cách xem testcase | B6: MỖI MODULE MỘT SHEET (34 sheet, tên dạng 'MÃ - Tên': HOME, AUTH, COMM, COURSE, FEED, PAY, ADM, ADM2, ADM3, SECX, MONEY, GAME, INFRA, PERF, SPLIT, WIZ, ANN, SETP, SETS, SETN, SETC, SETB, SETR, ROLE...). Bấm tên module ở bảng 'Thống kê theo Module' bên dưới để nhảy tới sheet; mỗi sheet có sẵn bộ lọc theo Chức năng/Loại test/Ưu tiên/Phù hợp Playwright và cột Mã TC + Chức năng được cố định khi cuộn ngang. Cột tiến độ Test 1/Test 2 (Pass/Fail/Chưa test) ở bảng thống kê tự cập nhật khi tester điền kết quả.
A7: Sheet phụ | B7: 'Tài khoản & dữ liệu test' (tài khoản/dữ liệu seed, cách dựng môi trường) · 'Nhật ký thay đổi' · 'Bằng chứng (ảnh)' (ảnh Playwright)
A8: Người soạn thảo | B8: QA/Tester
A9: Tổng số test case | B9: 4028
A11: Chú giải cột 'Trạng thái tính năng'
A12: Đã hoàn thiện | B12: Tính năng đã được xây dựng thật, có thể test/thực thi ngay bây giờ.
A13: Kế hoạch | B13: Tính năng đã đặc tả nghiệp vụ trong BRD nhưng chưa được xây dựng — test case chuẩn bị sẵn, thực thi khi tính năng hoàn thành.
A15: Chú giải cột 'Trạng thái test' (điền khi thực thi)
A16: Chưa test
A17: Pass
A18: Fail
A19: Blocked
A20: N/A
A22: Chú giải cột 'Phù hợp Playwright' & mô hình 2 người test
A23: Có | B23: Tự động hóa tốt bằng Playwright Test (UI flow, form, API request, kể cả nhiều case bảo mật như IDOR/JWT/CSRF/rate-limit qua APIRequestContext). Giao cho Người test 1.
A24: Một phần | B24: Automate được 1 phần (VD webhook giả lập, Stripe test mode, responsive/SEO) nhưng cần xác minh thêm thủ công song song.
A25: Không | B25: Nên test thủ công: cần đọc email/OTP thật, cổng thanh toán nội địa có xác thực ngân hàng (VNPay/MoMo/PayOS), load test (dùng k6/Artillery), đối soát dữ liệu/DB.
A27: Người test 1 | B27: Test bằng Playwright Test (có script tự động) — điền tên vào cột 'Người test 1', kết quả vào 'Trạng thái test 1', đường dẫn/link bằng chứng (trace viewer, video, screenshot report) vào cột 'Evidences'.
A28: Người test 2 | B28: Test thủ công (manual) — điền tên vào cột 'Người test 2', kết quả vào 'Trạng thái test 2'. Bắt buộc với mọi case có Phù hợp Playwright = 'Không', khuyến khích chạy song song để đối chiếu với các case 'Có'/'Một phần'.
A30: Thống kê theo Module
A31: Mã Module | B31: Tên Module | C31: Tổng số TC | D31: Đã hoàn thiện | E31: Kế hoạch | F31: Playwright: Có | G31: Playwright: Một phần/Không | H31: Test 1: Pass | I31: Test 2: Pass | J31: Fail (T1+T2) | K31: Chưa test (T1) | L31: Chưa test (T2)
A32: HOME | B32: Trang chủ & Khám phá | C32: =COUNTA('HOME - Trang chủ & Khám phá'!$A$2:$A$5000) | D32: =COUNTIF('HOME - Trang chủ & Khám phá'!$G:$G,"Đã hoàn thiện") | E32: =COUNTIF('HOME - Trang chủ & Khám phá'!$G:$G,"Kế hoạch") | F32: =COUNTIF('HOME - Trang chủ & Khám phá'!$H:$H,"Có") | G32: =C32-F32 | H32: =COUNTIF('HOME - Trang chủ & Khám phá'!$N:$N,"Pass") | I32: =COUNTIF('HOME - Trang chủ & Khám phá'!$Q:$Q,"Pass") | J32: =COUNTIF('HOME - Trang chủ & Khám phá'!$N:$N,"Fail")+COUNTIF('HOME - Trang chủ & Khám phá'!$Q:$Q,"Fail") | K32: =COUNTIF('HOME - Trang chủ & Khám phá'!$N:$N,"Chưa test") | L32: =COUNTIF('HOME - Trang chủ & Khám phá'!$Q:$Q,"Chưa test")
A33: AUTH | B33: Tài khoản & Xác thực | C33: =COUNTA('AUTH - Tài khoản & Xác thực'!$A$2:$A$5000) | D33: =COUNTIF('AUTH - Tài khoản & Xác thực'!$G:$G,"Đã hoàn thiện") | E33: =COUNTIF('AUTH - Tài khoản & Xác thực'!$G:$G,"Kế hoạch") | F33: =COUNTIF('AUTH - Tài khoản & Xác thực'!$H:$H,"Có") | G33: =C33-F33 | H33: =COUNTIF('AUTH - Tài khoản & Xác thực'!$N:$N,"Pass") | I33: =COUNTIF('AUTH - Tài khoản & Xác thực'!$Q:$Q,"Pass") | J33: =COUNTIF('AUTH - Tài khoản & Xác thực'!$N:$N,"Fail")+COUNTIF('AUTH - Tài khoản & Xác thực'!$Q:$Q,"Fail") | K33: =COUNTIF('AUTH - Tài khoản & Xác thực'!$N:$N,"Chưa test") | L33: =COUNTIF('AUTH - Tài khoản & Xác thực'!$Q:$Q,"Chưa test")
A34: COMM | B34: Cộng đồng | C34: =COUNTA('COMM - Cộng đồng'!$A$2:$A$5000) | D34: =COUNTIF('COMM - Cộng đồng'!$G:$G,"Đã hoàn thiện") | E34: =COUNTIF('COMM - Cộng đồng'!$G:$G,"Kế hoạch") | F34: =COUNTIF('COMM - Cộng đồng'!$H:$H,"Có") | G34: =C34-F34 | H34: =COUNTIF('COMM - Cộng đồng'!$N:$N,"Pass") | I34: =COUNTIF('COMM - Cộng đồng'!$Q:$Q,"Pass") | J34: =COUNTIF('COMM - Cộng đồng'!$N:$N,"Fail")+COUNTIF('COMM - Cộng đồng'!$Q:$Q,"Fail") | K34: =COUNTIF('COMM - Cộng đồng'!$N:$N,"Chưa test") | L34: =COUNTIF('COMM - Cộng đồng'!$Q:$Q,"Chưa test")
A35: COMMVP | B35: Cộng đồng MVP (gắn theo khóa học — 2026-09-29) | C35: =COUNTA('COMMVP - Cộng đồng MVP'!$A$2:$A$5000) | D35: =COUNTIF('COMMVP - Cộng đồng MVP'!$G:$G,"Đã hoàn thiện") | E35: =COUNTIF('COMMVP - Cộng đồng MVP'!$G:$G,"Kế hoạch") | F35: =COUNTIF('COMMVP - Cộng đồng MVP'!$H:$H,"Có") | G35: =C35-F35 | H35: =COUNTIF('COMMVP - Cộng đồng MVP'!$N:$N,"Pass") | I35: =COUNTIF('COMMVP - Cộng đồng MVP'!$Q:$Q,"Pass") | J35: =COUNTIF('COMMVP - Cộng đồng MVP'!$N:$N,"Fail")+COUNTIF('COMMVP - Cộng đồng MVP'!$Q:$Q,"Fail") | K35: =COUNTIF('COMMVP - Cộng đồng MVP'!$N:$N,"Chưa test") | L35: =COUNTIF('COMMVP - Cộng đồng MVP'!$Q:$Q,"Chưa test")
A36: COURSE | B36: Khóa học / Lớp học | C36: =COUNTA('COURSE - Lớp học'!$A$2:$A$5000) | D36: =COUNTIF('COURSE - Lớp học'!$G:$G,"Đã hoàn thiện") | E36: =COUNTIF('COURSE - Lớp học'!$G:$G,"Kế hoạch") | F36: =COUNTIF('COURSE - Lớp học'!$H:$H,"Có") | G36: =C36-F36 | H36: =COUNTIF('COURSE - Lớp học'!$N:$N,"Pass") | I36: =COUNTIF('COURSE - Lớp học'!$Q:$Q,"Pass") | J36: =COUNTIF('COURSE - Lớp học'!$N:$N,"Fail")+COUNTIF('COURSE - Lớp học'!$Q:$Q,"Fail") | K36: =COUNTIF('COURSE - Lớp học'!$N:$N,"Chưa test") | L36: =COUNTIF('COURSE - Lớp học'!$Q:$Q,"Chưa test")
A37: FEED | B37: Bảng tin & Tương tác cộng đồng | C37: =COUNTA('FEED - Bảng tin'!$A$2:$A$5000) | D37: =COUNTIF('FEED - Bảng tin'!$G:$G,"Đã hoàn thiện") | E37: =COUNTIF('FEED - Bảng tin'!$G:$G,"Kế hoạch") | F37: =COUNTIF('FEED - Bảng tin'!$H:$H,"Có") | G37: =C37-F37 | H37: =COUNTIF('FEED - Bảng tin'!$N:$N,"Pass") | I37: =COUNTIF('FEED - Bảng tin'!$Q:$Q,"Pass") | J37: =COUNTIF('FEED - Bảng tin'!$N:$N,"Fail")+COUNTIF('FEED - Bảng tin'!$Q:$Q,"Fail") | K37: =COUNTIF('FEED - Bảng tin'!$N:$N,"Chưa test") | L37: =COUNTIF('FEED - Bảng tin'!$Q:$Q,"Chưa test")
A38: EVENT | B38: Lịch & Sự kiện | C38: =COUNTA('EVENT - Lịch & Sự kiện'!$A$2:$A$5000) | D38: =COUNTIF('EVENT - Lịch & Sự kiện'!$G:$G,"Đã hoàn thiện") | E38: =COUNTIF('EVENT - Lịch & Sự kiện'!$G:$G,"Kế hoạch") | F38: =COUNTIF('EVENT - Lịch & Sự kiện'!$H:$H,"Có") | G38: =C38-F38 | H38: =COUNTIF('EVENT - Lịch & Sự kiện'!$N:$N,"Pass") | I38: =COUNTIF('EVENT - Lịch & Sự kiện'!$Q:$Q,"Pass") | J38: =COUNTIF('EVENT - Lịch & Sự kiện'!$N:$N,"Fail")+COUNTIF('EVENT - Lịch & Sự kiện'!$Q:$Q,"Fail") | K38: =COUNTIF('EVENT - Lịch & Sự kiện'!$N:$N,"Chưa test") | L38: =COUNTIF('EVENT - Lịch & Sự kiện'!$Q:$Q,"Chưa test")
A39: NOTI | B39: Thông báo & Nhắn tin | C39: =COUNTA('NOTI - Thông báo & Nhắn tin'!$A$2:$A$5000) | D39: =COUNTIF('NOTI - Thông báo & Nhắn tin'!$G:$G,"Đã hoàn thiện") | E39: =COUNTIF('NOTI - Thông báo & Nhắn tin'!$G:$G,"Kế hoạch") | F39: =COUNTIF('NOTI - Thông báo & Nhắn tin'!$H:$H,"Có") | G39: =C39-F39 | H39: =COUNTIF('NOTI - Thông báo & Nhắn tin'!$N:$N,"Pass") | I39: =COUNTIF('NOTI - Thông báo & Nhắn tin'!$Q:$Q,"Pass") | J39: =COUNTIF('NOTI - Thông báo & Nhắn tin'!$N:$N,"Fail")+COUNTIF('NOTI - Thông báo & Nhắn tin'!$Q:$Q,"Fail") | K39: =COUNTIF('NOTI - Thông báo & Nhắn tin'!$N:$N,"Chưa test") | L39: =COUNTIF('NOTI - Thông báo & Nhắn tin'!$Q:$Q,"Chưa test")
A40: PAY | B40: Thanh toán & Gói thành viên | C40: =COUNTA('PAY - Thanh toán & Gói'!$A$2:$A$5000) | D40: =COUNTIF('PAY - Thanh toán & Gói'!$G:$G,"Đã hoàn thiện") | E40: =COUNTIF('PAY - Thanh toán & Gói'!$G:$G,"Kế hoạch") | F40: =COUNTIF('PAY - Thanh toán & Gói'!$H:$H,"Có") | G40: =C40-F40 | H40: =COUNTIF('PAY - Thanh toán & Gói'!$N:$N,"Pass") | I40: =COUNTIF('PAY - Thanh toán & Gói'!$Q:$Q,"Pass") | J40: =COUNTIF('PAY - Thanh toán & Gói'!$N:$N,"Fail")+COUNTIF('PAY - Thanh toán & Gói'!$Q:$Q,"Fail") | K40: =COUNTIF('PAY - Thanh toán & Gói'!$N:$N,"Chưa test") | L40: =COUNTIF('PAY - Thanh toán & Gói'!$Q:$Q,"Chưa test")
A41: ADMIN | B41: Quản trị & Vận hành hệ thống | C41: =COUNTA('ADMIN - Quản trị & Kiểm duyệt'!$A$2:$A$5000) | D41: =COUNTIF('ADMIN - Quản trị & Kiểm duyệt'!$G:$G,"Đã hoàn thiện") | E41: =COUNTIF('ADMIN - Quản trị & Kiểm duyệt'!$G:$G,"Kế hoạch") | F41: =COUNTIF('ADMIN - Quản trị & Kiểm duyệt'!$H:$H,"Có") | G41: =C41-F41 | H41: =COUNTIF('ADMIN - Quản trị & Kiểm duyệt'!$N:$N,"Pass") | I41: =COUNTIF('ADMIN - Quản trị & Kiểm duyệt'!$Q:$Q,"Pass") | J41: =COUNTIF('ADMIN - Quản trị & Kiểm duyệt'!$N:$N,"Fail")+COUNTIF('ADMIN - Quản trị & Kiểm duyệt'!$Q:$Q,"Fail") | K41: =COUNTIF('ADMIN - Quản trị & Kiểm duyệt'!$N:$N,"Chưa test") | L41: =COUNTIF('ADMIN - Quản trị & Kiểm duyệt'!$Q:$Q,"Chưa test")
A42: SEC | B42: Bảo mật & Yêu cầu phi chức năng | C42: =COUNTA('SEC - Bảo mật & Phi chức năng'!$A$2:$A$5000) | D42: =COUNTIF('SEC - Bảo mật & Phi chức năng'!$G:$G,"Đã hoàn thiện") | E42: =COUNTIF('SEC - Bảo mật & Phi chức năng'!$G:$G,"Kế hoạch") | F42: =COUNTIF('SEC - Bảo mật & Phi chức năng'!$H:$H,"Có") | G42: =C42-F42 | H42: =COUNTIF('SEC - Bảo mật & Phi chức năng'!$N:$N,"Pass") | I42: =COUNTIF('SEC - Bảo mật & Phi chức năng'!$Q:$Q,"Pass") | J42: =COUNTIF('SEC - Bảo mật & Phi chức năng'!$N:$N,"Fail")+COUNTIF('SEC - Bảo mật & Phi chức năng'!$Q:$Q,"Fail") | K42: =COUNTIF('SEC - Bảo mật & Phi chức năng'!$N:$N,"Chưa test") | L42: =COUNTIF('SEC - Bảo mật & Phi chức năng'!$Q:$Q,"Chưa test")
A43: ROLE | B43: Ma trận phân quyền & Bảo mật nâng cao | C43: =COUNTA('ROLE - Ma trận phân quyền'!$A$2:$A$5000) | D43: =COUNTIF('ROLE - Ma trận phân quyền'!$G:$G,"Đã hoàn thiện") | E43: =COUNTIF('ROLE - Ma trận phân quyền'!$G:$G,"Kế hoạch") | F43: =COUNTIF('ROLE - Ma trận phân quyền'!$H:$H,"Có") | G43: =C43-F43 | H43: =COUNTIF('ROLE - Ma trận phân quyền'!$N:$N,"Pass") | I43: =COUNTIF('ROLE - Ma trận phân quyền'!$Q:$Q,"Pass") | J43: =COUNTIF('ROLE - Ma trận phân quyền'!$N:$N,"Fail")+COUNTIF('ROLE - Ma trận phân quyền'!$Q:$Q,"Fail") | K43: =COUNTIF('ROLE - Ma trận phân quyền'!$N:$N,"Chưa test") | L43: =COUNTIF('ROLE - Ma trận phân quyền'!$Q:$Q,"Chưa test")
A44: INTEG | B44: API / Tích hợp & Concurrency | C44: =COUNTA('INTEG - API & Concurrency'!$A$2:$A$5000) | D44: =COUNTIF('INTEG - API & Concurrency'!$G:$G,"Đã hoàn thiện") | E44: =COUNTIF('INTEG - API & Concurrency'!$G:$G,"Kế hoạch") | F44: =COUNTIF('INTEG - API & Concurrency'!$H:$H,"Có") | G44: =C44-F44 | H44: =COUNTIF('INTEG - API & Concurrency'!$N:$N,"Pass") | I44: =COUNTIF('INTEG - API & Concurrency'!$Q:$Q,"Pass") | J44: =COUNTIF('INTEG - API & Concurrency'!$N:$N,"Fail")+COUNTIF('INTEG - API & Concurrency'!$Q:$Q,"Fail") | K44: =COUNTIF('INTEG - API & Concurrency'!$N:$N,"Chưa test") | L44: =COUNTIF('INTEG - API & Concurrency'!$Q:$Q,"Chưa test")
A45: MEMBER | B45: Thành viên, Hồ sơ & Xếp hạng | C45: =COUNTA('MEMBER - Thành viên & Xếp hạng'!$A$2:$A$5000) | D45: =COUNTIF('MEMBER - Thành viên & Xếp hạng'!$G:$G,"Đã hoàn thiện") | E45: =COUNTIF('MEMBER - Thành viên & Xếp hạng'!$G:$G,"Kế hoạch") | F45: =COUNTIF('MEMBER - Thành viên & Xếp hạng'!$H:$H,"Có") | G45: =C45-F45 | H45: =COUNTIF('MEMBER - Thành viên & Xếp hạng'!$N:$N,"Pass") | I45: =COUNTIF('MEMBER - Thành viên & Xếp hạng'!$Q:$Q,"Pass") | J45: =COUNTIF('MEMBER - Thành viên & Xếp hạng'!$N:$N,"Fail")+COUNTIF('MEMBER - Thành viên & Xếp hạng'!$Q:$Q,"Fail") | K45: =COUNTIF('MEMBER - Thành viên & Xếp hạng'!$N:$N,"Chưa test") | L45: =COUNTIF('MEMBER - Thành viên & Xếp hạng'!$Q:$Q,"Chưa test")
A46: CERT | B46: Chứng nhận | C46: =COUNTA('CERT - Chứng nhận'!$A$2:$A$5000) | D46: =COUNTIF('CERT - Chứng nhận'!$G:$G,"Đã hoàn thiện") | E46: =COUNTIF('CERT - Chứng nhận'!$G:$G,"Kế hoạch") | F46: =COUNTIF('CERT - Chứng nhận'!$H:$H,"Có") | G46: =C46-F46 | H46: =COUNTIF('CERT - Chứng nhận'!$N:$N,"Pass") | I46: =COUNTIF('CERT - Chứng nhận'!$Q:$Q,"Pass") | J46: =COUNTIF('CERT - Chứng nhận'!$N:$N,"Fail")+COUNTIF('CERT - Chứng nhận'!$Q:$Q,"Fail") | K46: =COUNTIF('CERT - Chứng nhận'!$N:$N,"Chưa test") | L46: =COUNTIF('CERT - Chứng nhận'!$Q:$Q,"Chưa test")
...

Sheet HOME - Trang chủ & Khám phá
A1: Mã Test Case | B1: Module | C1: Chức năng | D1: Tiêu đề Test Case | E1: Loại test | F1: Mức ưu tiên | G1: Trạng thái tính năng | H1: Phù hợp Playwright | I1: Tiền điều kiện | J1: Các bước thực hiện | K1: Dữ liệu test | L1: Kết quả mong đợi | M1: Người test 1 (Automation) | N1: Trạng thái test 1 | O1: Evidences | P1: Người test 2 (Manual) | Q1: Trạng thái test 2 | R1: Ghi chú / Kết quả thực tế / Bug ref
A2: TC-HOME-001 | B2: Trang chủ & Khám phá | C2: Tìm kiếm khóa học | D2: Tìm kiếm theo từ khóa trong tiêu đề khóa học | E2: Chức năng | F2: Cao | G2: Đã hoàn thiện | H2: Có | I2: Đã có dữ liệu khóa học mẫu trên trang khám phá | J2: 1. Vào trang khám phá khóa học 2. Nhập từ khóa khớp tiêu đề 1 khóa học vào ô tìm kiếm 3. Bấm Enter / nút tìm kiếm | K2: Từ khóa: một phần tiêu đề khóa học có sẵn | L2: Danh sách kết quả chỉ hiển thị (các) khóa học có tiêu đề chứa từ khóa | M2: Claude (Playwright automation) | N2: Pass | O2: Không có ảnh riêng (test bị bỏ qua) — trace đầy đủ: e2e/report/index.html (chỉ mở được khi tải file .xlsx và mở Excel local) | P2: Linh | Q2: Pass
A3: TC-HOME-002 | B3: Trang chủ & Khám phá | C3: Tìm kiếm khóa học | D3: Tìm kiếm theo từ khóa trong mô tả khóa học | E3: Chức năng | F3: Trung bình | G3: Đã hoàn thiện | H3: Có | I3: Đã có dữ liệu khóa học mẫu | J3: 1. Vào trang khám phá 2. Nhập từ khóa chỉ xuất hiện trong phần mô tả (không có trong tiêu đề) 3. Bấm tìm kiếm | K3: Từ khóa xuất hiện trong mô tả khóa học | L3: Khóa học có từ khóa trong mô tả vẫn được trả về trong kết quả | M3: Claude (Playwright automation) | N3: Pass | O3: Không có ảnh riêng (test bị bỏ qua) — trace đầy đủ: e2e/report/index.html (chỉ mở được khi tải file .xlsx và mở Excel local) | P3: Linh | Q3: Pass
A4: TC-HOME-003 | B4: Trang chủ & Khám phá | C4: Tìm kiếm khóa học | D4: Tìm kiếm theo tên giảng viên | E4: Chức năng | F4: Trung bình | G4: Đã hoàn thiện | H4: Có | I4: Đã có dữ liệu khóa học mẫu | J4: 1. Vào trang khám phá 2. Nhập tên một giảng viên đang có khóa học 3. Bấm tìm kiếm | K4: Tên giảng viên có thật trong dữ liệu | L4: Trả về đúng các khóa học của giảng viên đó | M4: Claude (Playwright automation) | N4: Pass | O4: Không có ảnh riêng (test bị bỏ qua) — trace đầy đủ: e2e/report/index.html (chỉ mở được khi tải file .xlsx và mở Excel local) | P4: Linh | Q4: Pass
A5: TC-HOME-004 | B5: Trang chủ & Khám phá | C5: Tìm kiếm khóa học | D5: Tìm kiếm với từ khóa không tồn tại | E5: Chức năng | F5: Trung bình | G5: Đã hoàn thiện | H5: Có | I5: Đã có dữ liệu khóa học mẫu | J5: 1. Vào trang khám phá 2. Nhập từ khóa ngẫu nhiên không khớp bất kỳ khóa học nào 3. Bấm tìm kiếm | K5: VD: 'zzzxyz123' | L5: Hiển thị thông báo/khu vực 'Không tìm thấy kết quả', không lỗi trang trắng | M5: Claude (Playwright automation) | N5: Pass | O5: Không có ảnh riêng (test bị bỏ qua) — trace đầy đủ: e2e/report/index.html (chỉ mở được khi tải file .xlsx và mở Excel local) | P5: Linh | Q5: Pass
A6: TC-HOME-005 | B6: Trang chủ & Khám phá | C6: Tìm kiếm khóa học | D6: Tìm kiếm với ô tìm kiếm để trống | E6: Chức năng | F6: Thấp | G6: Đã hoàn thiện | H6: Có | I6: Đã có dữ liệu khóa học mẫu | J6: 1. Vào trang khám phá 2. Để trống ô tìm kiếm và bấm tìm kiếm (hoặc không nhập gì) | K6: Không có input | L6: Hiển thị lại toàn bộ danh sách khóa học mặc định, không lỗi | M6: Claude (Playwright automation) | N6: Pass | O6: Không có ảnh riêng (test bị bỏ qua) — trace đầy đủ: e2e/report/index.html (chỉ mở được khi tải file .xlsx và mở Excel local) | P6: Linh | Q6: Pass
A7: TC-HOME-006 | B7: Trang chủ & Khám phá | C7: Tìm kiếm khóa học | D7: Tìm kiếm chứa ký tự đặc biệt / script injection | E7: Bảo mật | F7: Cao | G7: Đã hoàn thiện | H7: Có | I7: Đã có dữ liệu khóa học mẫu | J7: 1. Vào trang khám phá 2. Nhập chuỗi dạng <script>alert(1)</script> hoặc ' OR 1=1 -- vào ô tìm kiếm 3. Bấm tìm kiếm | K7: <script>alert(1)</script> | L7: Không thực thi script, không lỗi hệ thống, trả về danh sách rỗng hoặc không khớp | M7: Claude (Playwright automation) | N7: Pass | O7: Không có ảnh riêng (test bị bỏ qua) — trace đầy đủ: e2e/report/index.html (chỉ mở được khi tải file .xlsx và mở Excel local) | P7: Linh | Q7: Pass
A8: TC-HOME-007 | B8: Trang chủ & Khám phá | C8: Lọc theo danh mục | D8: Lọc danh sách theo 1 danh mục (VD: Công nghệ) | E8: Chức năng | F8: Cao | G8: Đã hoàn thiện | H8: Có | I8: Có khóa học thuộc nhiều danh mục khác nhau | J8: 1. Vào trang khám phá 2. Chọn danh mục 'Công nghệ' trong bộ lọc | K8: Danh mục: Công nghệ | L8: Chỉ hiển thị khóa học thuộc danh mục Công nghệ | M8: Claude (Playwright automation) | N8: Pass | O8: Không có ảnh riêng (test bị bỏ qua) — trace đầy đủ: e2e/report/index.html (chỉ mở được khi tải file .xlsx và mở Excel local) | P8: Linh | Q8: Pass
A9: TC-HOME-010 | B9: Trang chủ & Khám phá | C9: Bộ lọc nâng cao | D9: Lọc theo loại công khai/riêng tư | E9: Chức năng | F9: Trung bình | G9: Đã hoàn thiện | H9: Có | I9: Có cả khóa học công khai và riêng tư trong dữ liệu | J9: 1. Vào trang khám phá 2. Mở bộ lọc nâng cao 3. Chọn loại 'Riêng tư' | K9: Loại: Riêng tư | L9: Chỉ hiển thị khóa học/cộng đồng ở chế độ riêng tư | M9: Claude (Playwright automation) | N9: Pass | O9: Không có ảnh riêng (test bị bỏ qua) — trace đầy đủ: e2e/report/index.html (chỉ mở được khi tải file .xlsx và mở Excel local) | P9: Linh | Q9: Pass
A10: TC-HOME-011 | B10: Trang chủ & Khám phá | C10: Bộ lọc nâng cao | D10: Lọc theo trạng thái khóa học | E10: Chức năng | F10: Thấp | G10: Đã hoàn thiện | H10: Có | I10: Dữ liệu có khóa học ở nhiều trạng thái | J10: 1. Vào trang khám phá 2. Mở bộ lọc nâng cao 3. Chọn 1 trạng thái cụ thể | K10: Trạng thái: đang mở | L10: Kết quả chỉ gồm khóa học đúng trạng thái đã chọn | M10: Claude (Playwright automation) | N10: Pass | O10: Không có ảnh riêng (test bị bỏ qua) — trace đầy đủ: e2e/report/index.html (chỉ mở được khi tải file .xlsx và mở Excel local) | P10: Linh | Q10: Pass
A11: TC-HOME-012 | B11: Trang chủ & Khám phá | C11: Bộ lọc nâng cao | D11: Lọc theo ngôn ngữ | E11: Chức năng | F11: Thấp | G11: Đã hoàn thiện | H11: Có | I11: Dữ liệu có khóa học đa ngôn ngữ | J11: 1. Vào trang khám phá 2. Mở bộ lọc nâng cao 3. Chọn ngôn ngữ 'Tiếng Việt' | K11: Ngôn ngữ: Tiếng Việt | L11: Chỉ hiển thị khóa học có ngôn ngữ giảng dạy là Tiếng Việt | M11: Claude (Playwright automation) | N11: Pass | O11: Không có ảnh riêng (test bị bỏ qua) — trace đầy đủ: e2e/report/index.html (chỉ mở được khi tải file .xlsx và mở Excel local) | P11: Linh | Q11: Pass
A12: TC-HOME-013 | B12: Trang chủ & Khám phá | C12: Bộ lọc nâng cao | D12: Kết hợp nhiều bộ lọc cùng lúc (danh mục + giá + loại) | E12: Chức năng | F12: Cao | G12: Đã hoàn thiện | H12: Có | I12: Dữ liệu đa dạng danh mục/giá/loại | J12: 1. Vào trang khám phá 2. Chọn tab danh mục 'Công nghệ', dropdown 'Giá' = 'Có phí' và dropdown 'Loại' = 'Công khai' cùng lúc | K12: Danh mục=Công nghệ; Giá=Có phí; Loại=Công khai | L12: Kết quả thỏa mãn đồng thời tất cả điều kiện lọc (logic AND giữa các nhóm filter), số 'Tìm thấy N' cập nhật, về trang 1 | M12: Claude (Playwright automation) | N12: Pass | O12: Không có ảnh riêng (test bị bỏ qua) — trace đầy đủ: e2e/report/index.html (chỉ mở được khi tải file .xlsx và mở Excel local) | P12: Linh | Q12: Pass
A13: TC-HOME-014 | B13: Trang chủ & Khám phá | C13: Bộ lọc nâng cao | D13: Xóa/reset toàn bộ bộ lọc | E13: Chức năng | F13: Trung bình | G13: Đã hoàn thiện | H13: Có | I13: Đã áp dụng ít nhất 1 bộ lọc | J13: 1. Áp dụng vài bộ lọc 2. Bấm nút 'Xóa bộ lọc' / 'Reset' | K13: - | L13: Toàn bộ điều kiện lọc bị xóa, danh sách quay về mặc định | M13: Claude (Playwright automation) | N13: Pass | O13: Không có ảnh riêng (test bị bỏ qua) — trace đầy đủ: e2e/report/index.html (chỉ mở được khi tải file .xlsx và mở Excel local) | P13: Linh | Q13: Pass
... A20: TC-HOME-021 | B20: Trang chủ & Khám phá | C20: Số liệu nổi bật (hero) | D20: Kiểm tra số liệu tổng học viên/khóa học/đánh giá hiển thị đúng | E20: Chức năng | F20: Trung bình | G20: Đã hoàn thiện | H20: Có | I20: Có dữ liệu trong DB (đã chạy seed) | J20: 1. Vào trang chủ 2. Đối chiếu 4 số liệu ở khu vực hero (học viên, cộng đồng, chủ cộng đồng, điểm đánh giá trung bình) với GET /api/stats và với SQL trong DB | K20: - | L20: Số liệu khớp GET /api/stats (tính từ DB: người dùng thật, cộng đồng đang liệt kê, chủ cộng đồng, trung bình review thật); khi chưa có đánh giá thật hiển thị '–' (rating = null), không còn số bịa | M20: Claude (Playwright automation) | N20: Pass | O20: Không có ảnh riêng (test bị bỏ qua) — trace đầy đủ: e2e/report/index.html (chỉ mở được khi tải file .xlsx và mở Excel local) | P20: Linh | Q20: Pass
A21: TC-HOME-023 | B21: Trang chủ & Khám phá | C21: Tìm kiếm khóa học | D21: Tìm kiếm không phân biệt hoa/thường | E21: Chức năng | F21: Trung bình | G21: Đã hoàn thiện | H21: Có | I21: - | J21: 1. Vào trang khám phá 2. Nhập từ khóa toàn chữ HOA trùng với tiêu đề khóa học viết thường 3. Bấm tìm kiếm | K21: VD: 'KHOA HOC JAVA' cho khóa học 'Khóa học Java' | L21: Trả về đúng kết quả bất kể hoa/thường | M21: Claude (Playwright automation) | N21: Pass | O21: Không có ảnh riêng (test bị bỏ qua) — trace đầy đủ: e2e/report/index.html (chỉ mở được khi tải file .xlsx và mở Excel local) | P21: Linh | Q21: Fail | R21: Chỉ cho tìm kiếm title
A22: TC-HOME-024 | B22: Trang chủ & Khám phá | C22: Tìm kiếm khóa học | D22: Tìm kiếm với khoảng trắng thừa ở đầu/cuối từ khóa | E22: Chức năng | F22: Thấp | G22: Đã hoàn thiện | H22: Có | I22: - | J22: 1. Nhập từ khóa có khoảng trắng thừa đầu/cuối 2. Bấm tìm kiếm | K22: ' java ' | L22: Hệ thống tự trim khoảng trắng, trả về kết quả đúng như không có khoảng trắng thừa | M22: Claude (Playwright automation) | N22: Pass | O22: Không có ảnh riêng (test bị bỏ qua) — trace đầy đủ: e2e/report/index.html (chỉ mở được khi tải file .xlsx và mở Excel local) | P22: Linh | Q22: Pass
A23: TC-HOME-025 | B23: Trang chủ & Khám phá | C23: Tìm kiếm khóa học | D23: Tìm kiếm không dấu vẫn ra kết quả có dấu tiếng Việt | E23: Chức năng | F23: Trung bình | G23: Đã hoàn thiện | H23: Có | I23: - | J23: 1. Vào trang khám phá 2. Nhập từ khóa không dấu (VD: 'dau tu') 3. Bấm tìm kiếm | K23: 'dau tu' cho cộng đồng 'Đầu tư cho người mới' (seed fin) | L23: Trả về đúng cộng đồng có dấu tương ứng: tìm không dấu ĐÃ được hỗ trợ (Postgres full-text gập dấu bằng sf_fold(), đ -> d; GET /courses?q dùng cùng bộ khớp - backend/docs/api/search.md) | M23: Claude (Playwright automation) | N23: Pass | O23: Không có ảnh riêng (test bị bỏ qua) — trace đầy đủ: e2e/report/index.html (chỉ mở được khi tải file .xlsx và mở Excel local) | P23: Linh | Q23: Pass
A24: TC-HOME-030 | B24: Trang chủ & Khám phá | C24: Kết hợp bộ lọc | D24: Giữ nguyên điều kiện tìm kiếm/lọc/sắp xếp khi chuyển trang | E24: Chức năng | F24: Cao | G24: Đã hoàn thiện | H24: Có | I24: - | J24: 1. Áp dụng tìm kiếm + lọc danh mục + sắp xếp 'Mới nhất' 2. Chuyển sang trang kết quả tiếp theo | K24: - | L24: Trang tiếp theo vẫn giữ đúng điều kiện tìm kiếm/lọc/sắp xếp đã chọn, không bị reset | M24: Claude (Playwright automation) | N24: Pass | O24: Không có ảnh riêng (test bị bỏ qua) — trace đầy đủ: e2e/report/index.html (chỉ mở được khi tải file .xlsx và mở Excel local) | P24: Linh | Q24: Pass
A25: TC-HOME-031 | B25: Trang chủ & Khám phá | C25: Phân quyền hiển thị | D25: Khách (Guest) xem được trang khám phá không cần đăng nhập | E25: Chức năng | F25: Trung bình | G25: Đã hoàn thiện | H25: Có | I25: Chưa đăng nhập | J25: 1. Mở trang khám phá ở chế độ ẩn danh (không đăng nhập) | K25: - | L25: Xem được danh sách, tìm kiếm, lọc bình thường theo đúng quyền của vai trò Khách | M25: Claude (Playwright automation) | N25: Pass | O25: Không có ảnh riêng (test bị bỏ qua) — trace đầy đủ: e2e/report/index.html (chỉ mở được khi tải file .xlsx và mở Excel local) | P25: Linh | Q25: Pass
A26: TC-HOME-032 | B26: Trang chủ & Khám phá | C26: Phân quyền hiển thị | D26: Khách bấm 'Tham gia ngay' bị chuyển hướng sang trang Đăng ký/Đăng nhập | E26: Chức năng | F26: Cao | G26: Đã hoàn thiện | H26: Có | I26: Chưa đăng nhập | J26: 1. Mở trang chi tiết khóa học ở chế độ ẩn danh 2. Bấm 'Tham gia ngay' | K26: - | L26: Chuyển hướng sang trang Đăng ký (hoặc Đăng nhập), sau khi hoàn tất quay lại đúng khóa học ban đầu | M26: Claude (Playwright automation) | N26: Pass | O26: Không có ảnh riêng (test bị bỏ qua) — trace đầy đủ: e2e/report/index.html (chỉ mở được khi tải file .xlsx và mở Excel local) | P26: Linh | Q26: Pass
A27: TC-HOME-033 | B27: Trang chủ & Khám phá | C27: Danh mục | D27: Chọn lần lượt các danh mục: mỗi lúc chỉ một danh mục được chọn, 'Tất cả' để bỏ lọc | E27: Chức năng | F27: Trung bình | G27: Đã hoàn thiện | H27: Có | I27: Có cộng đồng thuộc nhiều danh mục khác nhau | J27: 1. Vào trang khám phá 2. Bấm tab danh mục 'Công nghệ', rồi bấm tab 'Kinh doanh' 3. Bấm tab 'Tất cả' | K27: Danh mục: Công nghệ -> Kinh doanh -> Tất cả | L27: Mỗi lúc chỉ MỘT danh mục được chọn (tab chuyển trạng thái, KHÔNG cộng dồn nhiều danh mục); danh sách và số 'Tìm thấy N' đổi theo danh mục vừa chọn, về trang 1; 'Tất cả' bỏ lọc danh mục | N27: Chưa test | P27: Linh | Q27: Pass
A28: TC-HOME-034 | B28: Trang chủ & Khám phá | C28: Phân trang | D28: Nút 'Trang sau' bị vô hiệu hóa ở trang kết quả cuối cùng | E28: Chức năng | F28: Thấp | G28: Đã hoàn thiện | H28: Có | I28: Số lượng cộng đồng vượt 1 trang (12/trang) | J28: 1. Vào trang khám phá 2. Bấm 'Trang sau' liên tục tới trang cuối | K28: - | L28: Ở trang cuối nút 'Trang sau' bị disabled (Pagination: disabled khi page = totalPages), không gọi thêm API, không lỗi. Phân trang là state cục bộ, KHÔNG nằm trên URL | N28: Chưa test | P28: Linh | Q28: Pass
A29: TC-HOME-035 | B29: Trang chủ & Khám phá | C29: Phân trang | D29: Nút 'Trang trước' bị vô hiệu hóa ở trang 1 | E29: Chức năng | F29: Thấp | G29: Đã hoàn thiện | H29: Có | I29: Đang ở trang 1 của danh sách khám phá | J29: 1. Vào trang khám phá (trang 1) 2. Quan sát nút 'Trang trước' | K29: - | L29: Nút 'Trang trước' bị disabled ở trang 1 (disabled khi page = 1) | N29: Chưa test | P29: Linh | Q29: Pass
A30: TC-HOME-036 | B30: Trang chủ & Khám phá | C30: Phân trang | D30: API GET /api/courses kiểm tra tham số phân trang: page=0/-1/1001 bị 400, trang vượt tổng trả danh sách rỗng | E30: Chức năng | F30: Thấp | G30: Đã hoàn thiện | H30: Không | I30: Backend đang chạy | J30: 1. Gọi GET /api/courses?page=0 và ?page=-1 2. Gọi GET /api/courses?page=1001 3. Gọi GET /api/courses?page=999 (hợp lệ nhưng vượt tổng số trang) | K30: page=0 / -1 / 1001 / 999 | L30: page=0, -1, 1001: 400 VALIDATION_ERROR (page min 1, trần MAX_PAGE=1000 - catalog.schema.ts); page=999: 200 với data rỗng và meta.totalPages đúng, không lỗi 500. FE không đồng bộ trang lên URL nên chỉ kiểm bằng API | N30: Chưa test | P30: Linh | Q30: Pass

Sheet AUTH - Tài khoản & Xác thực
A1: Mã Test Case | B1: Module | C1: Chức năng | D1: Tiêu đề Test Case | E1: Loại test | F1: Mức ưu tiên | G1: Trạng thái tính năng | H1: Phù hợp Playwright | I1: Tiền điều kiện | J1: Các bước thực hiện | K1: Dữ liệu test | L1: Kết quả mong đợi | M1: Người test 1 (Automation) | N1: Trạng thái test 1 | O1: Evidences | P1: Người test 2 (Manual) | Q1: Trạng thái test 2 | R1: Ghi chú / Kết quả thực tế / Bug ref
A2: TC-AUTH-001 | B2: Tài khoản & Xác thực | C2: Đăng ký | D2: Đăng ký tài khoản thành công với thông tin hợp lệ | E2: Chức năng | F2: Cao | G2: Đã hoàn thiện | H2: Có | I2: Email chưa từng đăng ký trên hệ thống | J2: 1. Vào trang Đăng ký 2. Nhập họ tên, email hợp lệ, mật khẩu đạt yêu cầu (>=8 ký tự, có chữ hoa, ký tự đặc biệt) 3. Cuộn đọc hết Điều khoản sử dụng và Chính sách bảo mật 4. Tick đồng ý điều khoản 5. Bấm Đăng ký | K2: Email: test01@sofinhub.test / Mật khẩu: Test@1234 | L2: Tài khoản được tạo thành công, tự động đăng nhập hoặc chuyển tới trang đăng nhập/trang trước đó | M2: Claude (Playwright automation) | N2: Pass | O2: Không có ảnh riêng (test bị bỏ qua) — trace đầy đủ: e2e/report/index.html (chỉ mở được khi tải file .xlsx và mở Excel local) | P2: Linh | Q2: Fail | R2: Thêm mã xác minh gmail
A3: TC-AUTH-002 | B3: Tài khoản & Xác thực | C3: Đăng ký | D3: Đăng ký với email đã tồn tại | E3: Chức năng | F3: Cao | G3: Đã hoàn thiện | H3: Có | I3: Email đã có tài khoản trên hệ thống | J3: 1. Vào trang Đăng ký 2. Nhập email đã tồn tại 3. Điền các trường còn lại hợp lệ 4. Bấm Đăng ký | K3: Email đã tồn tại trong hệ thống | L3: Hiển thị lỗi 'Email đã được sử dụng', không tạo tài khoản trùng | M3: Claude (Playwright automation) | N3: Pass | O3: Không có ảnh riêng (test bị bỏ qua) — trace đầy đủ: e2e/report/index.html (chỉ mở được khi tải file .xlsx và mở Excel local) | P3: Linh | Q3: Chưa test
A4: TC-AUTH-003 | B4: Tài khoản & Xác thực | C4: Đăng ký | D4: Đăng ký với email sai định dạng | E4: Chức năng | F4: Trung bình | G4: Đã hoàn thiện | H4: Có | I4: - | J4: 1. Vào trang Đăng ký 2. Nhập email sai định dạng (VD: abc@.com) 3. Bấm Đăng ký | K4: Email: abc@.com | L4: Hiển thị lỗi validate định dạng email, không cho submit | M4: Claude (Playwright automation) | N4: Pass | O4: Không có ảnh riêng (test bị bỏ qua) — trace đầy đủ: e2e/report/index.html (chỉ mở được khi tải file .xlsx và mở Excel local) | P4: Linh | Q4: Pass
A5: TC-AUTH-004 | B5: Tài khoản & Xác thực | C5: Đăng ký | D5: Mật khẩu ít hơn 8 ký tự bị từ chối | E5: Chức năng | F5: Cao | G5: Đã hoàn thiện | H5: Có | I5: - | J5: 1. Vào trang Đăng ký 2. Nhập mật khẩu 7 ký tự (VD: Ab@123) 3. Bấm Đăng ký | K5: Mật khẩu: Ab@12 | L5: Hiển thị lỗi yêu cầu tối thiểu 8 ký tự, không tạo tài khoản | M5: Claude (Playwright automation) | N5: Pass | O5: Không có ảnh riêng (test bị bỏ qua) — trace đầy đủ: e2e/report/index.html (chỉ mở được khi tải file .xlsx và mở Excel local) | P5: Linh | Q5: Pass
A6: TC-AUTH-005 | B6: Tài khoản & Xác thực | C6: Đăng ký | D6: Mật khẩu không có chữ hoa bị từ chối | E6: Chức năng | F6: Cao | G6: Đã hoàn thiện | H6: Có | I6: - | J6: 1. Vào trang Đăng ký 2. Nhập mật khẩu toàn chữ thường + ký tự đặc biệt (VD: test@1234) 3. Bấm Đăng ký | K6: Mật khẩu: test@1234 | L6: Hiển thị lỗi yêu cầu có ít nhất 1 chữ hoa | M6: Claude (Playwright automation) | N6: Pass | O6: Không có ảnh riêng (test bị bỏ qua) — trace đầy đủ: e2e/report/index.html (chỉ mở được khi tải file .xlsx và mở Excel local) | P6: Linh | Q6: Pass
A7: TC-AUTH-006 | B7: Tài khoản & Xác thực | C7: Đăng ký | D7: Mật khẩu không có ký tự đặc biệt bị từ chối | E7: Chức năng | F7: Cao | G7: Đã hoàn thiện | H7: Có | I7: - | J7: 1. Vào trang Đăng ký 2. Nhập mật khẩu chữ hoa+thường+số nhưng không có ký tự đặc biệt (VD: Test1234) 3. Bấm Đăng ký | K7: Mật khẩu: Test1234 | L7: Hiển thị lỗi yêu cầu có ít nhất 1 ký tự đặc biệt | M7: Claude (Playwright automation) | N7: Pass | O7: Không có ảnh riêng (test bị bỏ qua) — trace đầy đủ: e2e/report/index.html (chỉ mở được khi tải file .xlsx và mở Excel local) | P7: Linh | Q7: Pass
A8: TC-AUTH-007 | B8: Tài khoản & Xác thực | C8: Đăng ký | D8: Để trống trường họ tên | E8: Chức năng | F8: Trung bình | G8: Đã hoàn thiện | H8: Có | I8: - | J8: 1. Vào trang Đăng ký 2. Để trống họ tên, điền các trường còn lại hợp lệ 3. Bấm Đăng ký | K8: Họ tên: (trống) | L8: Hiển thị lỗi bắt buộc nhập họ tên, không submit được | M8: Claude (Playwright automation) | N8: Pass | O8: Không có ảnh riêng (test bị bỏ qua) — trace đầy đủ: e2e/report/index.html (chỉ mở được khi tải file .xlsx và mở Excel local) | P8: Linh | Q8: Pass
A9: TC-AUTH-008 | B9: Tài khoản & Xác thực | C9: Đồng ý điều khoản | D9: Tick được ô đồng ý ngay, không cần mở/đọc Điều khoản sử dụng | E9: Chức năng | F9: Cao | G9: Đã hoàn thiện | H9: Có | I9: Đang ở trang Đăng ký | J9: 1. Điền thông tin hợp lệ 2. Tick ô đồng ý mà không bấm vào link Điều khoản/Chính sách nào | K9: - | L9: Ô tick đồng ý dùng được ngay (không bị disabled), nút Đăng ký bật; link Điều khoản và Chính sách vẫn mở được | M9: Claude (Playwright automation) | N9: Pass | O9: Không có ảnh riêng (test bị bỏ qua) — trace đầy đủ: e2e/report/index.html (chỉ mở được khi tải file .xlsx và mở Excel local) | Q9: Chưa test
A10: TC-AUTH-009 | B10: Tài khoản & Xác thực | C10: Đồng ý điều khoản | D10: Mở Chính sách bảo mật rồi quay lại: bản nháp form giữ nguyên, ô đồng ý vẫn dùng được | E10: Chức năng | F10: Trung bình | G10: Đã hoàn thiện | H10: Có | I10: Đã điền một phần form đăng ký | J10: 1. Bấm link Chính sách bảo mật 2. Bấm Quay lại đăng ký | K10: - | L10: Dữ liệu đã nhập còn nguyên; ô đồng ý không bị khóa | M10: Claude (Playwright automation) | N10: Pass | O10: Không có ảnh riêng (test bị bỏ qua) — trace đầy đủ: e2e/report/index.html (chỉ mở được khi tải file .xlsx và mở Excel local) | Q10: Chưa test
A11: TC-AUTH-010 | B11: Tài khoản & Xác thực | C11: Đồng ý điều khoản | D11: Không cho đăng ký khi chưa tick đồng ý điều khoản | E11: Chức năng | F11: Cao | G11: Đã hoàn thiện | H11: Có | I11: - | J11: 1. Điền đầy đủ thông tin đăng ký hợp lệ 2. Không tick đồng ý điều khoản 3. Bấm Đăng ký | K11: - | L11: Hệ thống chặn submit / báo lỗi yêu cầu đồng ý điều khoản trước khi đăng ký | M11: Claude (Playwright automation) | N11: Pass | O11: Không có ảnh riêng (test bị bỏ qua) — trace đầy đủ: e2e/report/index.html (chỉ mở được khi tải file .xlsx và mở Excel local) | P11: Linh | Q11: Fail | R11: Khi click vào Đồng ý điều khoản thì form nhập bị clear hết Khi chưa click vào button đồng ý mà vẫn click vào checkbox được
A12: TC-AUTH-011 | B12: Tài khoản & Xác thực | C12: Đăng ký | D12: Kiểm tra input chống XSS/SQL injection ở các trường đăng ký | E12: Bảo mật | F12: Cao | G12: Đã hoàn thiện | H12: Có | I12: - | J12: 1. Vào trang Đăng ký 2. Nhập chuỗi <script>alert(1)</script> hoặc ' OR '1'='1 vào trường họ tên/email 3. Bấm Đăng ký | K12: <script>alert(1)</script> | L12: Không thực thi script, dữ liệu được escape/validate, không gây lỗi hệ thống hoặc rò rỉ dữ liệu | M12: Claude (Playwright automation) | N12: Pass | O12: Không có ảnh riêng (test bị bỏ qua) — trace đầy đủ: e2e/report/index.html (chỉ mở được khi tải file .xlsx và mở Excel local) | P12: Linh | Q12: Pass
A13: TC-AUTH-012 | B13: Tài khoản & Xác thực | C13: Đăng nhập | D13: Đăng nhập thành công với email/mật khẩu đúng | E13: Chức năng | F13: Cao | G13: Đã hoàn thiện | H13: Có | I13: Tài khoản đã tồn tại và active | J13: 1. Vào trang Đăng nhập 2. Nhập đúng email và mật khẩu đã đăng ký 3. Bấm Đăng nhập | K13: Email/mật khẩu hợp lệ đã đăng ký trước đó | L13: Đăng nhập thành công, chuyển hướng vào hệ thống với đúng phiên người dùng | M13: Claude (Playwright automation) | N13: Pass | O13: Không có ảnh riêng (test bị bỏ qua) — trace đầy đủ: e2e/report/index.html (chỉ mở được khi tải file .xlsx và mở Excel local) | P13: Linh | Q13: Pass
A14: TC-AUTH-013 | B14: Tài khoản & Xác thực | C14: Đăng nhập | D14: Đăng nhập với mật khẩu sai | E14: Chức năng | F14: Cao | G14: Đã hoàn thiện | H14: Có | I14: Tài khoản đã tồn tại | J14: 1. Vào trang Đăng nhập 2. Nhập đúng email, sai mật khẩu 3. Bấm Đăng nhập | K14: Email đúng / mật khẩu sai | L14: Hiển thị lỗi thông tin đăng nhập không đúng, không cho vào hệ thống | M14: Claude (Playwright automation) | N14: Pass | O14: Không có ảnh riêng (test bị bỏ qua) — trace đầy đủ: e2e/report/index.html (chỉ mở được khi tải file .xlsx và mở Excel local) | P14: Linh | Q14: Pass
A15: TC-AUTH-014 | B15: Tài khoản & Xác thực | C15: Đăng nhập | D15: Đăng nhập với email không tồn tại | E15: Chức năng | F15: Trung bình | G15: Đã hoàn thiện | H15: Có | I15: - | J15: 1. Vào trang Đăng nhập 2. Nhập email chưa từng đăng ký 3. Bấm Đăng nhập | K15: Email không tồn tại | L15: Hiển thị lỗi chung (không tiết lộ email có tồn tại hay không), không cho vào hệ thống | M15: Claude (Playwright automation) | N15: Pass | O15: Không có ảnh riêng (test bị bỏ qua) — trace đầy đủ: e2e/report/index.html (chỉ mở được khi tải file .xlsx và mở Excel local) | P15: Linh | Q15: Pass
A16: TC-AUTH-015 | B16: Tài khoản & Xác thực | C16: Đăng nhập | D16: Giới hạn số lần đăng nhập sai liên tiếp (chống dò mật khẩu) | E16: Bảo mật | F16: Cao | G16: Đã hoàn thiện | H16: Có | I16: Tài khoản đã tồn tại. Nên chạy CUỐI phiên test: case làm cạn quota đăng nhập sai của IP máy test (10 lần SAI/15 phút/IP, bộ đếm theo từng instance BE) nên các test đăng nhập khác sẽ bị 429 tới khi restart BE hoặc hết 15 phút | J16: 1. Vào trang Đăng nhập (hoặc gọi POST /api/auth/login) 2. Nhập sai mật khẩu liên tục tới khi bị chặn (tối đa ~11 lần) | K16: Mật khẩu sai lặp lại (> 10 lần/15 phút từ cùng IP) | L16: Từ lần SAI thứ 11 trong cửa sổ 15 phút (sớm hơn nếu IP đã có lần sai trước đó) API trả 429 TOO_MANY_REQUESTS 'Đăng nhập sai quá nhiều lần, vui lòng thử lại sau ít phút' và FE hiển thị lỗi; chỉ đếm lần đăng nhập THẤT BẠI (loginLimiter trong auth.routes.ts) | M16: Claude (Playwright automation) | N16: Pass | O16: Không có ảnh riêng (test bị bỏ qua) — trace đầy đủ: e2e/report/index.html (chỉ mở được khi tải file .xlsx và mở Excel local) | P16: Linh | Q16: Pass | R16: Số lần thử trước khi bị 429: 6
A17: TC-AUTH-016 | B17: Tài khoản & Xác thực | C17: Phiên đăng nhập | D17: Phiên đăng nhập được giữ khi tải lại trang (F5) | E17: Chức năng | F17: Cao | G17: Đã hoàn thiện | H17: Có | I17: Đã đăng nhập thành công | J17: 1. Đăng nhập vào hệ thống 2. Nhấn F5 để tải lại trang | K17: - | L17: Người dùng vẫn ở trạng thái đã đăng nhập, không bị đẩy về trang chủ/đăng nhập | M17: Claude (Playwright automation) | N17: Pass | O17: Không có ảnh riêng (test bị bỏ qua) — trace đầy đủ: e2e/report/index.html (chỉ mở được khi tải file .xlsx và mở Excel local) | P17: Linh | Q17: Pass
A18: TC-AUTH-017 | B18: Tài khoản & Xác thực | C18: Đăng xuất | D18: Đăng xuất khỏi hệ thống | E18: Chức năng | F18: Cao | G18: Đã hoàn thiện | H18: Có | I18: Đã đăng nhập | J18: 1. Đang đăng nhập, bấm nút Đăng xuất | K18: - | L18: Phiên bị hủy, chuyển về trang chủ ở trạng thái khách (guest) | M18: Claude (Playwright automation) | N18: Pass | O18: Không có ảnh riêng (test bị bỏ qua) — trace đầy đủ: e2e/report/index.html (chỉ mở được khi tải file .xlsx và mở Excel local) | P18: Linh | Q18: Pass
A19: TC-AUTH-018 | B19: Tài khoản & Xác thực | C19: Đăng xuất | D19: Sau khi đăng xuất, không thể truy cập lại trang yêu cầu đăng nhập bằng nút Back | E19: Bảo mật | F19: Trung bình | G19: Đã hoàn thiện | H19: Có | I19: Vừa đăng xuất | J19: 1. Đăng xuất khỏi hệ thống 2. Bấm nút Back của trình duyệt để quay lại trang yêu cầu đăng nhập | K19: - | L19: Hệ thống yêu cầu đăng nhập lại, không hiển thị lại nội dung đã cache của phiên cũ | M19: Claude (Playwright automation) | N19: Pass | O19: Không có ảnh riêng (test bị bỏ qua) — trace đầy đủ: e2e/report/index.html (chỉ mở được khi tải file .xlsx và mở Excel local) | P19: Linh | Q19: Fail
A20: TC-AUTH-019 | B20: Tài khoản & Xác thực | C20: Đăng nhập mạng xã hội | D20: Đăng nhập bằng Google | E20: Chức năng | F20: Trung bình | G20: Kế hoạch | H20: Có | I20: Chưa làm (Kế hoạch): nút Google ở /login chỉ hiện 'Tính năng sắp ra mắt' và chưa gọi API (xem TC-AUTH-069) | J20: 1. Vào trang Đăng nhập 2. Bấm nút Đăng nhập bằng Google 3. Chọn tài khoản Google | K20: Tài khoản Google hợp lệ | L20: Đăng nhập/tạo tài khoản thành công liên kết với Google | N20: Chưa test | P20: Linh | Q20: Chưa test | R20: Tính năng sắp ra mắt
A21: TC-AUTH-020 | B21: Tài khoản & Xác thực | C21: Đăng nhập mạng xã hội | D21: Đăng nhập bằng Facebook | E21: Chức năng | F21: Trung bình | G21: Kế hoạch | H21: Có | I21: Chưa làm (Kế hoạch): nút Facebook ở /login chỉ hiện 'Tính năng sắp ra mắt' và chưa gọi API (xem TC-AUTH-069) | J21: 1. Vào trang Đăng nhập 2. Bấm nút Đăng nhập bằng Facebook 3. Xác nhận quyền truy cập | K21: Tài khoản Facebook hợp lệ | L21: Đăng nhập/tạo tài khoản thành công liên kết với Facebook | N21: Chưa test | P21: Linh | Q21: Chưa test | R21: Tính năng sắp ra mắt
A22: TC-AUTH-024 | B22: Tài khoản & Xác thực | C22: Xác thực 2 lớp (2FA) | D22: Bật 2FA cho tài khoản Owner/Admin | E22: Bảo mật | F22: Trung bình | G22: Kế hoạch | H22: Không | I22: Chưa làm (Kế hoạch): chưa có 2FA cho người dùng/Owner; 2FA của nhân viên admin chỉ lưu cấu hình, chưa thực thi (docs/OPEN_DECISIONS A14; xem TC-AUTH-071) | J22: 1. Vào Cài đặt bảo mật tài khoản 2. Bật 2FA 3. Quét mã QR bằng app xác thực 4. Nhập mã xác nhận | K22: - | L22: 2FA được kích hoạt, lần đăng nhập tiếp theo yêu cầu nhập mã OTP | N22: Chưa test | P22: Linh | Q22: Chưa test | R22: Tính năng sắp ra mắt
A23: TC-AUTH-025 | B23: Tài khoản & Xác thực | C23: Đăng ký | D23: Mật khẩu đúng đủ 8 ký tự (giá trị biên) được chấp nhận | E23: Chức năng | F23: Trung bình | G23: Đã hoàn thiện | H23: Có | I23: - | J23: 1. Nhập mật khẩu chính xác 8 ký tự thỏa quy tắc 2. Hoàn tất các trường khác hợp lệ 3. Bấm Đăng ký | K23: Mật khẩu 8 ký tự: 'Aa1@bcde' | L23: Đăng ký thành công, không bị từ chối ở giá trị biên dưới | M23: Claude (Playwright automation) | N23: Pass | O23: Không có ảnh riêng (test bị bỏ qua) — trace đầy đủ: e2e/report/index.html (chỉ mở được khi tải file .xlsx và mở Excel local) | P23: Linh | Q23: Pass
A24: TC-AUTH-026 | B24: Tài khoản & Xác thực | C24: Đăng ký | D24: Họ tên chứa ký tự tiếng Việt có dấu | E24: Chức năng | F24: Thấp | G24: Đã hoàn thiện | H24: Có | I24: - | J24: 1. Nhập họ tên có dấu tiếng Việt đầy đủ 2. Hoàn tất đăng ký | K24: Họ tên: Nguyễn Văn Ánh | L24: Đăng ký thành công, họ tên hiển thị đúng dấu ở mọi nơi (hồ sơ, bình luận...) | M24: Claude (Playwright automation) | N24: Pass | O24: Không có ảnh riêng (test bị bỏ qua) — trace đầy đủ: e2e/report/index.html (chỉ mở được khi tải file .xlsx và mở Excel local) | P24: Linh | Q24: Pass
A25: TC-AUTH-027 | B25: Tài khoản & Xác thực | C25: Đăng ký | D25: Email chuẩn hóa chữ hoa/thường khi kiểm tra trùng lặp | E25: Chức năng | F25: Cao | G25: Đã hoàn thiện | H25: Có | I25: Email 'test01@sofinhub.test' đã đăng ký trước đó | J25: 1. Đăng ký lại với email viết hoa toàn bộ hoặc khác hoa/thường | K25: TEST01@SofinHub.test | L25: Hệ thống nhận diện là email đã tồn tại, không cho tạo tài khoản trùng do khác biệt hoa/thường | M25: Claude (Playwright automation) | N25: Pass | O25: Không có ảnh riêng (test bị bỏ qua) — trace đầy đủ: e2e/report/index.html (chỉ mở được khi tải file .xlsx và mở Excel local) | P25: Linh | Q25: Pass
A26: TC-AUTH-028 | B26: Tài khoản & Xác thực | C26: Đăng ký | D26: Mật khẩu chứa khoảng trắng ở giữa | E26: Chức năng | F26: Thấp | G26: Đã hoàn thiện | H26: Có | I26: - | J26: 1. Nhập mật khẩu có khoảng trắng ở giữa 2. Bấm Đăng ký | K26: 'Ab@12 34' | L26: Hệ thống chấp nhận hoặc từ chối rõ ràng theo quy tắc đã định nghĩa, hành vi nhất quán giữa FE và BE | M26: Claude (Playwright automation) | N26: Pass | O26: Không có ảnh riêng (test bị bỏ qua) — trace đầy đủ: e2e/report/index.html (chỉ mở được khi tải file .xlsx và mở Excel local) | P26: Linh | Q26: Pass
A27: TC-AUTH-029 | B27: Tài khoản & Xác thực | C27: Đăng nhập | D27: Tài khoản bị tạm khóa do đăng nhập sai nhiều lần vẫn từ chối dù nhập đúng mật khẩu | E27: Bảo mật | F27: Cao | G27: Đã hoàn thiện | H27: Có | I27: Vừa vượt ngưỡng 10 lần đăng nhập sai/15 phút từ cùng IP (đây là giới hạn THEO IP, không phải khóa riêng tài khoản) | J27: 1. Đăng nhập sai đủ số lần để nhận 429 2. Ngay sau đó đăng nhập với email/mật khẩu ĐÚNG của cùng tài khoản | K27: - | L27: Vẫn 429 (bị chặn dù mật khẩu đúng) cho tới khi hết cửa sổ 15 phút. Lưu ý đây là rate limit theo IP chứ không phải khóa tài khoản (xem case 'Giới hạn đăng nhập sai tính theo IP...' cuối module) | M27: Claude (Playwright automation) | N27: Pass | O27: Không có ảnh riêng (test bị bỏ qua) — trace đầy đủ: e2e/report/index.html (chỉ mở được khi tải file .xlsx và mở Excel local) | P27: Linh | Q27: Pass | R27: Thêm box đếm ngược thời gian đợi
A28: TC-AUTH-030 | B28: Tài khoản & Xác thực | C28: Đăng nhập | D28: Đăng nhập đồng thời trên nhiều thiết bị khác nhau không bị đá nhau | E28: Chức năng | F28: Trung bình | G28: Đã hoàn thiện | H28: Có | I28: - | J28: 1. Đăng nhập tài khoản A trên trình duyệt 1 2. Đăng nhập cùng tài khoản A trên trình duyệt 2 3. Thao tác trên cả 2 trình duyệt | K28: - | L28: Cả 2 phiên đều hoạt động bình thường song song (trừ khi có yêu cầu nghiệp vụ giới hạn 1 thiết bị) | M28: Claude (Playwright automation) | N28: Pass | O28: Không có ảnh riêng (test bị bỏ qua) — trace đầy đủ: e2e/report/index.html (chỉ mở được khi tải file .xlsx và mở Excel local) | P28: Linh | Q28: Fail | R28: khi đăng nhập bài 1 thiết bị khác đang hiển thị "Đăng nhập sai quá nhiều lần, vui lòng thử lại sau ít phút"
A29: TC-AUTH-031 | B29: Tài khoản & Xác thực | C29: Phiên đăng nhập | D29: Access token bị chỉnh sửa (tamper) bị từ chối | E29: Bảo mật | F29: Cao | G29: Đã hoàn thiện | H29: Có | I29: Có access token hợp lệ | J29: 1. Lấy access token hợp lệ 2. Sửa đổi 1 ký tự bất kỳ trong token 3. Gọi API cần xác thực với token đã sửa | K29: - | L29: API trả về lỗi xác thực thất bại (401), không xử lý request | M29: Claude (Playwright automation) | N29: Pass | O29: Không có ảnh riêng (test bị bỏ qua) — trace đầy đủ: e2e/report/index.html (chỉ mở được khi tải file .xlsx và mở Excel local) | P29: Linh | Q29: Chưa test
A30: TC-AUTH-032 | B30: Tài khoản & Xác thực | C30: Phiên đăng nhập | D30: Refresh token hết hạn không dùng lại được | E30: Bảo mật | F30: Cao | G30: Đã hoàn thiện | H30: Có | I30: Có refresh token đã hết hạn theo cấu hình | J30: 1. Chờ refresh token hết hạn (hoặc dùng token test đã hết hạn) 2. Gọi API làm mới access token bằng refresh token đó | K30: - | L30: Bị từ chối, yêu cầu đăng nhập lại từ đầu | M30: Claude (Playwright automation) | N30: N/A | O30: Không có ảnh riêng (test bị bỏ qua) — trace đầy đủ: e2e/report/index.html (chỉ mở được khi tải file .xlsx và mở Excel local) | P30: Linh | Q30: Chưa test | R30: BỎ QUA: REFRESH_TOKEN_TTL_DAYS=30 theo cấu hình — không thể chờ thật 30 ngày trong 1 lần chạy. Cần môi trường test riêng với TTL rút ngắn hoặc test-hook cấp sẵn refresh token hết hạn.
A31: TC-AUTH-033 | B31: Tài khoản & Xác thực | C31: Phiên đăng nhập | D31: Dùng token của tài khoản khác để giả mạo truy cập dữ liệu | E31: Bảo mật | F31: Cao | G31: Đã hoàn thiện | H31: Có | I31: Có 2 tài khoản test A và B, có access token hợp lệ của B | J31: 1. Đăng nhập tài khoản A trên trình duyệt 2. Thay access token trong request bằng token của B (qua DevTools/Postman) 3. Gọi API lấy dữ liệu cá nhân | K31: - | L31: Nếu token của B hợp lệ, hệ thống trả đúng dữ liệu của B — xác nhận hệ thống xác thực theo token chứ không nhầm lẫn theo session cũ, không rò rỉ chéo dữ liệu | M31: Claude (Playwright automation) | N31: Pass | O31: Không có ảnh riêng (test bị bỏ qua) — trace đầy đủ: e2e/report/index.html (chỉ mở được khi tải file .xlsx và mở Excel local) | P31: Linh | Q31: Chưa test
A32: TC-AUTH-035 | B32: Tài khoản & Xác thực | C32: Đăng ký | D32: Trường mật khẩu không hiển thị dạng plain text mặc định | E32: Giao diện | F32: Thấp | G32: Đã hoàn thiện | H32: Có | I32: - | J32: 1. Vào trang đăng ký 2. Nhập mật khẩu 3. Quan sát ô mật khẩu | K32: - | L32: Mật khẩu hiển thị dạng ẩn (dấu chấm/sao) mặc định, có tùy chọn hiện rõ nếu có icon con mắt | M32: Claude (Playwright automation) | N32: Pass | O32: Không có ảnh riêng (test bị bỏ qua) — trace đầy đủ: e2e/report/index.html (chỉ mở được khi tải file .xlsx và mở Excel local) | P32: Linh | Q32: Pass
A33: TC-AUTH-036 | B33: Tài khoản & Xác thực | C33: Đăng xuất | D33: API từ chối request dùng access token cũ ngay sau khi đăng xuất | E33: Bảo mật | F33: Cao | G33: Đã hoàn thiện | H33: Có | I33: Đã đăng nhập, có access token còn hiệu lực | J33: 1. Lấy access token hiện tại 2. Đăng xuất 3. Ngay lập tức gọi API cần xác thực bằng access token vừa lấy | K33: - | L33: API từ chối ngay bằng 401, không chờ access token hết hạn. LỖI CŨ ĐÃ SỬA: access token mang sid + tv, requireAuth/optionalAuth tra phiên và User.tokenVersion trong DB mỗi request (backend/docs/api/identity.md 'Thu hồi access token có hiệu lực NGAY'; tests/token-revocation.test.ts). Kết quả Fail trước đây là của bản cũ - CẦN CHẠY LẠI Test 1 | M33: Claude (Playwright automation) | N33: Fail | O33: Không có ảnh riêng (test bị bỏ qua) — trace đầy đủ: e2e/report/index.html (chỉ mở được khi tải file .xlsx và mở Excel local) | P33: Linh | Q33: Chưa test | R33: BUG/GAP: access token cũ vẫn dùng được sau khi đăng xuất (trả về 200 thay vì 401). Nguyên nhân: backend/src/modules/auth/tokens.ts — logout() chỉ revoke refresh token (revokeAllRefreshTokens), access token là JWT stateless không có cơ chế thu hồi/blacklist, nên vẫn hợp lệ cho tới khi tự hết hạn (15 phút). Access token bị lộ (XSS, log...) vẫn dùng được sau logout. || Lỗi assertion: Error: Xem annotation "finding" ở trên nếu test này FAIL — đây là gap bảo mật thật, không phải lỗi test expect(received).toBe(expected) // Object.is
A34: TC-AUTH-037 | B34: Tài khoản & Xác thực | C34: Đăng ký | D34: API đăng ký trả 200 kèm phiên, cookie refresh và user không lộ trường nội bộ | E34: Chức năng | F34: Cao | G34: Đã hoàn thiện | H34: Có | I34: Email chưa tồn tại, ví dụ qa.reg01@sofinhub.test | J34: 1. POST /api/auth/register với payload bên dưới 2. Kiểm tra status, body và header Set-Cookie 3. Gọi GET /api/auth/me với accessToken vừa nhận | K34: {"firstName":"Lan","lastName":"Tran","email":"qa.reg01@sofinhub.test","password":"Matkhau@123"} | L34: HTTP 200 (không phải 201). Body {data:{user,accessToken}}; user có id, email, firstName='Lan', lastName='Tran', emailVerified=false, createdAt; KHÔNG có passwordHash, tokenVersion, isDemo, deletedAt. Set-Cookie refresh_token; HttpOnly; Path=/api/auth; SameSite=Lax; Max-Age=2592000 (30 ngày) khi NODE_ENV=development (không Secure); NODE_ENV=test thêm Secure; production thêm Secure + SameSite=None (auth.routes.ts setRefreshCookie). GET /api/auth/me bằng accessToken trả 200 cùng user. | N34: Chưa test | Q34: Chưa test
A35: TC-AUTH-038 | B35: Tài khoản & Xác thực | C35: Đăng ký | D35: Đăng ký trùng email seed khác hoa/thường và có khoảng trắng hai đầu | E35: Chức năng | F35: Cao | G35: Đã hoàn thiện | H35: Có | I35: Tài khoản seed member1@sofinhub.test đã tồn tại | J35: 1. POST /api/auth/register với email viết hoa lẫn khoảng trắng đầu/cuối 2. Đăng nhập lại member1@sofinhub.test / Passw0rd!x để chắc chắn tài khoản cũ không bị đổi | K35: {"firstName":"Giả","lastName":"Mạo","email":" MEMBER1@SofinHub.Test ","password":"Matkhau@123"} | L35: HTTP 409, error.code=CONFLICT, message 'Email này đã được đăng ký' (schema trim + lowercase email trước khi kiểm tra trùng). Không tạo tài khoản mới; đăng nhập member1 vẫn thành công. | N35: Chưa test | P35: Linh | Q35: Pass
A36: TC-AUTH-039 | B36: Tài khoản & Xác thực | C36: Đăng ký | D36: Đăng ký thiếu toàn bộ trường trả lỗi validate theo từng trường | E36: Chức năng | F36: Trung bình | G36: Đã hoàn thiện | H36: Có | I36: - | J36: 1. POST /api/auth/register với body {} | K36: {} | L36: HTTP 400, error.code=VALIDATION_ERROR, message 'Tham số không hợp lệ', error.details.fieldErrors có đủ 4 khóa firstName, lastName, email, password. | N36: Chưa test | P36: Linh | Q36: Pass
A37: TC-AUTH-040 | B37: Tài khoản & Xác thực | C37: Đăng ký | D37: Tên/họ chỉ gồm khoảng trắng bị từ chối với thông điệp riêng từng trường | E37: Chức năng | F37: Trung bình | G37: Đã hoàn thiện | H37: Có | I37: - | J37: 1. POST /api/auth/register với firstName và lastName chỉ là khoảng trắng | K37: {"firstName":" ","lastName":" ","email":"qa.reg02@sofinhub.test","password":"Matkhau@123"} | L37: HTTP 400 VALIDATION_ERROR; fieldErrors.firstName chứa 'Vui lòng nhập tên', fieldErrors.lastName chứa 'Vui lòng nhập họ' (trim trước khi kiểm min 1). Không tạo user. | N37: Chưa test | P37: Linh | Q37: Pass
A38: TC-AUTH-041 | B38: Tài khoản & Xác thực | C38: Đăng ký | D38: Biên độ dài tên: 80 ký tự được chấp nhận, 81 ký tự bị từ chối | E38: Chức năng | F38: Thấp | G38: Đã hoàn thiện | H38: Có | I38: - | J38: 1. POST /api/auth/register với firstName = 'A' lặp 80 lần, email qa.reg03a@sofinhub.test 2. POST /api/auth/register với firstName = 'A' lặp 81 lần, email qa.reg03b@sofinhub.test | K38: firstName 80 và 81 ký tự; lastName='Bien'; password='Matkhau@123' | L38: Lần 1: HTTP 200, tên lưu nguyên 80 ký tự. Lần 2: HTTP 400 VALIDATION_ERROR (fieldErrors.firstName), email qa.reg03b chưa được tạo. | N38: Chưa test | P38: Linh | Q38: Fail
A39: TC-AUTH-042 | B39: Tài khoản & Xác thực | C39: Đăng ký | D39: Biên độ dài email 180 ký tự và mật khẩu 200 ký tự | E39: Chức năng | F39: Thấp | G39: Đã hoàn thiện | H39: Có | I39: - | J39: 1. Đăng ký với email dài 181 ký tự (local-part 'a' lặp 160 + '@sofinhub.test' cho tổng > 180) 2. Đăng ký với mật khẩu 201 ký tự: 'Aa@' + 'x' lặp 198 | K39: email >180 ký tự; password 201 ký tự | L39: Cả hai HTTP 400 VALIDATION_ERROR (email tối đa 180, mật khẩu tối đa 200). Mật khẩu đúng 200 ký tự thì được chấp nhận (200). | N39: Chưa test | P39: Linh | Q39: Fail
A40: TC-AUTH-043 | B40: Tài khoản & Xác thực | C40: Đăng ký | D40: Chữ hoa không phải ASCII (Đ, Ư) không thỏa quy tắc 'chữ in hoa' | E40: Chức năng | F40: Trung bình | G40: Đã hoàn thiện | H40: Có | I40: - | J40: 1. POST /api/auth/register với mật khẩu chỉ có chữ hoa Unicode và ký tự đặc biệt | K40: {"email":"qa.reg04@sofinhub.test","password":"đặng@khoa1Đ"}, firstName/lastName hợp lệ | L40: HTTP 400 VALIDATION_ERROR; fieldErrors.password chứa 'Mật khẩu cần ít nhất 1 chữ in hoa' (regex /[A-Z]/ chỉ khớp A-Z). | N40: Chưa test | P40: Linh | Q40: Pass
...

Sheet COMM - Cộng đồng
A1: Mã Test Case | B1: Module | C1: Chức năng | D1: Tiêu đề Test Case | E1: Loại test | F1: Mức ưu tiên | G1: Trạng thái tính năng | H1: Phù hợp Playwright | I1: Tiền điều kiện | J1: Các bước thực hiện | K1: Dữ liệu test | L1: Kết quả mong đợi | M1: Người test 1 (Automation) | N1: Trạng thái test 1 | O1: Evidences | P1: Người test 2 (Manual) | Q1: Trạng thái test 2 | R1: Ghi chú / Kết quả thực tế / Bug ref
A2: TC-COMM-010 | B2: Cộng đồng | C2: Trang cộng đồng | D2: Tab Giới thiệu hiển thị đúng thông tin cộng đồng | E2: Giao diện | F2: Thấp | G2: Đã hoàn thiện | H2: Có | I2: - | J2: 1. Vào /communities/:id/community 2. Chọn mục 'Giới thiệu' ở thanh bên (/communities/:id/community/gioi-thieu) | K2: - | L2: Hiển thị thông tin chung (công khai/riêng tư, số thành viên, giá), mô tả, khối nội dung/lớp học và thông tin chủ cộng đồng đúng như đã cấu hình (dữ liệu thật từ API, không còn mẫu) | N2: Chưa test | P2: Linh | Q2: Pass
A3: TC-COMM-026 | B3: Cộng đồng | C3: Tham gia cộng đồng | D3: Thành viên từng bị loại khỏi cộng đồng riêng tư gửi lại yêu cầu tham gia | E3: Chức năng | F3: Trung bình | G3: Đã hoàn thiện | H3: Có | I3: Thành viên đã từng bị Owner loại khỏi cộng đồng riêng tư | J3: 1. Thành viên đã bị loại trước đó vào lại trang cộng đồng riêng tư 2. Gửi yêu cầu tham gia lại | K3: - | L3: Yêu cầu mới được tạo bình thường (201, chờ duyệt): kick KHÔNG phải cấm - kick xóa ghi danh và thu hồi các yêu cầu 'approved' cũ (communities.service.kick). Nếu người đó bị CẤM (ban) thì 403 'Bạn đã bị cấm khỏi cộng đồng này' (xem TC-COMM-090) | N3: Chưa test | Q3: Chưa test
A4: TC-COMM-031 | B4: Cộng đồng | C4: Khám phá cộng đồng | D4: Cộng đồng riêng tư không hiển thị đầy đủ trên trang khám phá công khai | E4: Bảo mật | F4: Trung bình | G4: Đã hoàn thiện | H4: Có | I4: Có cả cộng đồng công khai và riêng tư | J4: 1. Vào trang khám phá cộng đồng ở chế độ Khách/chưa tham gia | K4: - | L4: Cộng đồng riêng tư vẫn xuất hiện trong danh sách Khám phá (có thể lọc 'Loại: Riêng tư' - quyết định A12 trong docs/OPEN_DECISIONS.md chưa chốt) nhưng người chưa được duyệt chỉ thấy trang giới thiệu /communities/:id với nút 'Gửi yêu cầu tham gia'; nội dung các tab bị chặn (API 403, FE chuyển về trang giới thiệu). [PHỤ THUỘC QUYẾT ĐỊNH CHƯA CHỐT] | N4: Chưa test | P4: Linh | Q4: Pass
A5: TC-COMM-033 | B5: Cộng đồng | C5: Tạo cộng đồng (validate & slug) | D5: Slug cộng đồng sinh từ tên tiếng Việt có dấu (bỏ dấu, chữ đ -> d) | E5: Chức năng | F5: Cao | G5: Đã hoàn thiện | H5: Có | I5: Đã chạy npm run db:seed (BE :4000, FE :5173); mật khẩu chung mọi tài khoản seed là Passw0rd!x; PLATFORM_ADMIN_EMAILS chứa admin@sofinhub.test; đăng nhập API: POST /api/auth/login rồi gửi header Authorization: Bearer <accessToken>. Đăng nhập newbie@sofinhub.test; chưa có cộng đồng nào slug 'cong-dong-nhiep-anh-da-lat' | J5: 1. Vào /communities/new, bước 1 nhập tên, mô tả, chọn danh mục 'hobby', bước 2 chọn Công khai giá 0, bước 3 bấm 'Tạo cộng đồng' 2. Ghi lại URL sau khi chuyển trang 3. Gọi GET /api/communities/cong-dong-nhiep-anh-da-lat | K5: title='Cộng đồng Nhiếp ảnh Đà Lạt', description='Nơi chia sẻ ảnh', category=hobby, priceUsd=0, visibility=public | L5: POST /api/communities trả 201, data.id='cong-dong-nhiep-anh-da-lat', viewerRole='owner'; FE chuyển sang /communities/cong-dong-nhiep-anh-da-lat/community; GET chi tiết trả 200 | N5: Chưa test | P5: Linh | Q5: Pass
A6: TC-COMM-034 | B6: Cộng đồng | C6: Tạo cộng đồng (validate & slug) | D6: Tạo hai cộng đồng trùng tên: slug tự thêm hậu tố -2, -3 | E6: Chức năng | F6: Cao | G6: Đã hoàn thiện | H6: Có | I6: Đã chạy npm run db:seed (BE :4000, FE :5173); mật khẩu chung mọi tài khoản seed là Passw0rd!x; PLATFORM_ADMIN_EMAILS chứa admin@sofinhub.test; đăng nhập API: POST /api/auth/login rồi gửi header Authorization: Bearer <accessToken>. Đăng nhập owner@; chưa có slug 'qa-trung-ten' | J6: 1. POST /api/communities lần 1 với title 'QA Trung Ten' 2. Lặp lại lần 2 và lần 3 đúng payload cũ 3. GET /api/communities/qa-trung-ten, /qa-trung-ten-2, /qa-trung-ten-3 | K6: title='QA Trung Ten', description='x', category=business, priceUsd=0, visibility=public | L6: Lần 1 id='qa-trung-ten', lần 2 id='qa-trung-ten-2', lần 3 id='qa-trung-ten-3' (đều 201); ba cộng đồng độc lập, không ghi đè nhau | N6: Chưa test | P6: Linh | Q6: Pass
A7: TC-COMM-035 | B7: Cộng đồng | C7: Tạo cộng đồng (validate & slug) | D7: Tên chỉ gồm ký tự đặc biệt/emoji dùng slug dự phòng 'community' | E7: Chức năng | F7: Trung bình | G7: Đã hoàn thiện | H7: Có | I7: Đã chạy npm run db:seed (BE :4000, FE :5173); mật khẩu chung mọi tài khoản seed là Passw0rd!x; PLATFORM_ADMIN_EMAILS chứa admin@sofinhub.test; đăng nhập API: POST /api/auth/login rồi gửi header Authorization: Bearer <accessToken>. Đăng nhập newbie@; chưa có slug 'community' | J7: 1. POST /api/communities với title '!!!' (đủ 3 ký tự) 2. POST lần nữa với title '🔥🔥🔥' | K7: title='!!!' rồi '🔥🔥🔥'; các trường khác hợp lệ | L7: Cả hai trả 201 (qua kiểm tra độ dài 3-80); id lần 1='community', lần 2='community-2' (giá trị hành vi hiện tại; slug không mang nghĩa, cần quyết định có nên chặn tên toàn ký tự đặc biệt) | N7: Chưa test | P7: Linh | Q7: Pass
A8: TC-COMM-036 | B8: Cộng đồng | C8: Tạo cộng đồng (validate & slug) | D8: Slug bị cắt tối đa 50 ký tự khi tên rất dài (80 ký tự) | E8: Chức năng | F8: Thấp | G8: Đã hoàn thiện | H8: Có | I8: Đã chạy npm run db:seed (BE :4000, FE :5173); mật khẩu chung mọi tài khoản seed là Passw0rd!x; PLATFORM_ADMIN_EMAILS chứa admin@sofinhub.test; đăng nhập API: POST /api/auth/login rồi gửi header Authorization: Bearer <accessToken>. Đăng nhập newbie@ | J8: 1. POST /api/communities với title gồm 80 ký tự chữ thường 'a' cách nhau dấu cách 2. Đọc data.id trong response | K8: title = 'abcdefghij ' lặp đến đúng 80 ký tự (không kết thúc bằng khoảng trắng) | L8: 201; data.id dài <= 50 ký tự, không bắt đầu/kết thúc bằng '-', chỉ gồm [a-z0-9-] | N8: Chưa test | P8: Linh | Q8: Fail | R8: Chỉ được 30 ký tự
